apache flink closed 100 1
Traceback (most recent call last):
  File "/home/jiramed_withun/.conda/envs/ERAWAN_env/lib/python3.10/site-packages/urllib3/connection.py", line 174, in _new_conn
    conn = connection.create_connection(
  File "/home/jiramed_withun/.conda/envs/ERAWAN_env/lib/python3.10/site-packages/urllib3/util/connection.py", line 72, in create_connection
    for res in socket.getaddrinfo(host, port, family, socket.SOCK_STREAM):
  File "/home/jiramed_withun/.conda/envs/ERAWAN_env/lib/python3.10/socket.py", line 955, in getaddrinfo
    for res in _socket.getaddrinfo(host, port, family, type, proto, flags):
socket.gaierror: [Errno -2] Name or service not known

During handling of the above exception, another exception occurred:

Traceback (most recent call last):
  File "/home/jiramed_withun/.conda/envs/ERAWAN_env/lib/python3.10/site-packages/urllib3/connectionpool.py", line 714, in urlopen
    httplib_response = self._make_request(
  File "/home/jiramed_withun/.conda/envs/ERAWAN_env/lib/python3.10/site-packages/urllib3/connectionpool.py", line 403, in _make_request
    self._validate_conn(conn)
  File "/home/jiramed_withun/.conda/envs/ERAWAN_env/lib/python3.10/site-packages/urllib3/connectionpool.py", line 1053, in _validate_conn
    conn.connect()
  File "/home/jiramed_withun/.conda/envs/ERAWAN_env/lib/python3.10/site-packages/urllib3/connection.py", line 363, in connect
    self.sock = conn = self._new_conn()
  File "/home/jiramed_withun/.conda/envs/ERAWAN_env/lib/python3.10/site-packages/urllib3/connection.py", line 186, in _new_conn
    raise NewConnectionError(
urllib3.exceptions.NewConnectionError: <urllib3.connection.HTTPSConnection object at 0x7f410bd57070>: Failed to establish a new connection: [Errno -2] Name or service not known

During handling of the above exception, another exception occurred:

Traceback (most recent call last):
  File "/home/jiramed_withun/.conda/envs/ERAWAN_env/lib/python3.10/site-packages/requests/adapters.py", line 486, in send
    resp = conn.urlopen(
  File "/home/jiramed_withun/.conda/envs/ERAWAN_env/lib/python3.10/site-packages/urllib3/connectionpool.py", line 798, in urlopen
    retries = retries.increment(
  File "/home/jiramed_withun/.conda/envs/ERAWAN_env/lib/python3.10/site-packages/urllib3/util/retry.py", line 592, in increment
    raise MaxRetryError(_pool, url, error or ResponseError(cause))
urllib3.exceptions.MaxRetryError: HTTPSConnectionPool(host='api.github.com', port=443): Max retries exceeded with url: /repos/apache/flink/pulls?state=closed&per_page=100&page=1 (Caused by NewConnectionError('<urllib3.connection.HTTPSConnection object at 0x7f410bd57070>: Failed to establish a new connection: [Errno -2] Name or service not known'))

During handling of the above exception, another exception occurred:

Traceback (most recent call last):
  File "/project/ESERH/jiramed_withun_project/script_flink.py", line 157, in <module>
    df = s.save_pull_request('closed')
  File "/project/ESERH/jiramed_withun_project/script_flink.py", line 76, in save_pull_request
    pulls = CollectPulls.get_pulls_in_detail(eurl[0], eurl[1], state, 100, page, self.token)
  File "/project/ESERH/jiramed_withun_project/script_flink.py", line 53, in get_pulls_in_detail
    response = requests.get(url, headers=headers)
  File "/home/jiramed_withun/.conda/envs/ERAWAN_env/lib/python3.10/site-packages/requests/api.py", line 73, in get
    return request("get", url, params=params, **kwargs)
  File "/home/jiramed_withun/.conda/envs/ERAWAN_env/lib/python3.10/site-packages/requests/api.py", line 59, in request
    return session.request(method=method, url=url, **kwargs)
  File "/home/jiramed_withun/.conda/envs/ERAWAN_env/lib/python3.10/site-packages/requests/sessions.py", line 589, in request
    resp = self.send(prep, **send_kwargs)
  File "/home/jiramed_withun/.conda/envs/ERAWAN_env/lib/python3.10/site-packages/requests/sessions.py", line 703, in send
    r = adapter.send(request, **kwargs)
  File "/home/jiramed_withun/.conda/envs/ERAWAN_env/lib/python3.10/site-packages/requests/adapters.py", line 519, in send
    raise ConnectionError(e, request=request)
requests.exceptions.ConnectionError: HTTPSConnectionPool(host='api.github.com', port=443): Max retries exceeded with url: /repos/apache/flink/pulls?state=closed&per_page=100&page=1 (Caused by NewConnectionError('<urllib3.connection.HTTPSConnection object at 0x7f410bd57070>: Failed to establish a new connection: [Errno -2] Name or service not known'))
srun: error: compute1: task 0: Exited with exit code 1
