Traceback (most recent call last):
  File "/home/jiramed_withun/.conda/envs/ERAWAN_env/lib/python3.10/site-packages/urllib3/connection.py", line 174, in _new_conn
    conn = connection.create_connection(
  File "/home/jiramed_withun/.conda/envs/ERAWAN_env/lib/python3.10/site-packages/urllib3/util/connection.py", line 72, in create_connection
    for res in socket.getaddrinfo(host, port, family, socket.SOCK_STREAM):
  File "/home/jiramed_withun/.conda/envs/ERAWAN_env/lib/python3.10/socket.py", line 955, in getaddrinfo
    for res in _socket.getaddrinfo(host, port, family, type, proto, flags):
socket.gaierror: [Errno -2] Name or service not known

During handling of the above exception, another exception occurred:

Traceback (most recent call last):
  File "/home/jiramed_withun/.conda/envs/ERAWAN_env/lib/python3.10/site-packages/urllib3/connectionpool.py", line 714, in urlopen
    httplib_response = self._make_request(
  File "/home/jiramed_withun/.conda/envs/ERAWAN_env/lib/python3.10/site-packages/urllib3/connectionpool.py", line 403, in _make_request
    self._validate_conn(conn)
  File "/home/jiramed_withun/.conda/envs/ERAWAN_env/lib/python3.10/site-packages/urllib3/connectionpool.py", line 1053, in _validate_conn
    conn.connect()
  File "/home/jiramed_withun/.conda/envs/ERAWAN_env/lib/python3.10/site-packages/urllib3/connection.py", line 363, in connect
    self.sock = conn = self._new_conn()
  File "/home/jiramed_withun/.conda/envs/ERAWAN_env/lib/python3.10/site-packages/urllib3/connection.py", line 186, in _new_conn
    raise NewConnectionError(
urllib3.exceptions.NewConnectionError: <urllib3.connection.HTTPSConnection object at 0x7f4b43a87220>: Failed to establish a new connection: [Errno -2] Name or service not known

During handling of the above exception, another exception occurred:

Traceback (most recent call last):
  File "/home/jiramed_withun/.conda/envs/ERAWAN_env/lib/python3.10/site-packages/requests/adapters.py", line 486, in send
    resp = conn.urlopen(
  File "/home/jiramed_withun/.conda/envs/ERAWAN_env/lib/python3.10/site-packages/urllib3/connectionpool.py", line 798, in urlopen
    retries = retries.increment(
  File "/home/jiramed_withun/.conda/envs/ERAWAN_env/lib/python3.10/site-packages/urllib3/util/retry.py", line 592, in increment
    raise MaxRetryError(_pool, url, error or ResponseError(cause))
urllib3.exceptions.MaxRetryError: HTTPSConnectionPool(host='notify-api.line.me', port=443): Max retries exceeded with url: /api/notify (Caused by NewConnectionError('<urllib3.connection.HTTPSConnection object at 0x7f4b43a87220>: Failed to establish a new connection: [Errno -2] Name or service not known'))

During handling of the above exception, another exception occurred:

Traceback (most recent call last):
  File "/project/ESERH/jiramed_withun_project/script_flink.py", line 160, in <module>
    s.save_pull_request('closed')
  File "/project/ESERH/jiramed_withun_project/script_flink.py", line 74, in save_pull_request
    r = requests.post(self.line_url, headers=self.headers, data={'message': pr})
  File "/home/jiramed_withun/.conda/envs/ERAWAN_env/lib/python3.10/site-packages/requests/api.py", line 115, in post
    return request("post", url, data=data, json=json, **kwargs)
  File "/home/jiramed_withun/.conda/envs/ERAWAN_env/lib/python3.10/site-packages/requests/api.py", line 59, in request
    return session.request(method=method, url=url, **kwargs)
  File "/home/jiramed_withun/.conda/envs/ERAWAN_env/lib/python3.10/site-packages/requests/sessions.py", line 589, in request
    resp = self.send(prep, **send_kwargs)
  File "/home/jiramed_withun/.conda/envs/ERAWAN_env/lib/python3.10/site-packages/requests/sessions.py", line 703, in send
    r = adapter.send(request, **kwargs)
  File "/home/jiramed_withun/.conda/envs/ERAWAN_env/lib/python3.10/site-packages/requests/adapters.py", line 519, in send
    raise ConnectionError(e, request=request)
requests.exceptions.ConnectionError: HTTPSConnectionPool(host='notify-api.line.me', port=443): Max retries exceeded with url: /api/notify (Caused by NewConnectionError('<urllib3.connection.HTTPSConnection object at 0x7f4b43a87220>: Failed to establish a new connection: [Errno -2] Name or service not known'))
srun: error: compute1: task 0: Exited with exit code 1
